<?xml version="1.0" ?>
<!--
  Minimal URDF for the TurtleBot3 Burger in smooth_nav.
  For the full model use: turtlebot3_description/urdf/turtlebot3_burger.urdf.xacro
  This file provides a lightweight fallback for testing.
-->
<robot name="turtlebot3_burger" xmlns:xacro="http://www.ros.org/wiki/xacro">

  <!-- Base footprint -->
  <link name="base_footprint"/>

  <joint name="base_joint" type="fixed">
    <parent link="base_footprint"/>
    <child link="base_link"/>
    <origin xyz="0 0 0.010" rpy="0 0 0"/>
  </joint>

  <!-- Base link -->
  <link name="base_link">
    <visual>
      <origin xyz="-0.032 0 0.0" rpy="0 0 0"/>
      <geometry>
        <box size="0.140 0.140 0.143"/>
      </geometry>
      <material name="dark_grey">
        <color rgba="0.2 0.2 0.2 1.0"/>
      </material>
    </visual>
    <collision>
      <origin xyz="-0.032 0 0.070" rpy="0 0 0"/>
      <geometry>
        <box size="0.140 0.140 0.143"/>
      </geometry>
    </collision>
    <inertial>
      <mass value="1.0"/>
      <inertia ixx="0.001" ixy="0.0" ixz="0.0"
               iyy="0.001" iyz="0.0" izz="0.001"/>
    </inertial>
  </link>

  <!-- Left wheel -->
  <joint name="wheel_left_joint" type="continuous">
    <parent link="base_link"/>
    <child link="wheel_left_link"/>
    <origin xyz="0 0.08 0.023" rpy="-1.5708 0 0"/>
    <axis xyz="0 0 1"/>
  </joint>

  <link name="wheel_left_link">
    <visual>
      <geometry>
        <cylinder radius="0.033" length="0.018"/>
      </geometry>
      <material name="dark_grey"/>
    </visual>
    <collision>
      <geometry>
        <cylinder radius="0.033" length="0.018"/>
      </geometry>
    </collision>
    <inertial>
      <mass value="0.1"/>
      <inertia ixx="0.0001" ixy="0" ixz="0"
               iyy="0.0001" iyz="0" izz="0.0001"/>
    </inertial>
  </link>

  <!-- Right wheel -->
  <joint name="wheel_right_joint" type="continuous">
    <parent link="base_link"/>
    <child link="wheel_right_link"/>
    <origin xyz="0 -0.08 0.023" rpy="-1.5708 0 0"/>
    <axis xyz="0 0 1"/>
  </joint>

  <link name="wheel_right_link">
    <visual>
      <geometry>
        <cylinder radius="0.033" length="0.018"/>
      </geometry>
      <material name="dark_grey"/>
    </visual>
    <collision>
      <geometry>
        <cylinder radius="0.033" length="0.018"/>
      </geometry>
    </collision>
    <inertial>
      <mass value="0.1"/>
      <inertia ixx="0.0001" ixy="0" ixz="0"
               iyy="0.0001" iyz="0" izz="0.0001"/>
    </inertial>
  </link>

  <!-- Caster (ball caster) -->
  <joint name="caster_joint" type="fixed">
    <parent link="base_link"/>
    <child link="caster_link"/>
    <origin xyz="-0.081 0 -0.004" rpy="0 0 0"/>
  </joint>

  <link name="caster_link">
    <visual>
      <geometry>
        <sphere radius="0.005"/>
      </geometry>
      <material name="dark_grey"/>
    </visual>
    <collision>
      <geometry>
        <sphere radius="0.005"/>
      </geometry>
    </collision>
    <inertial>
      <mass value="0.01"/>
      <inertia ixx="0.00001" ixy="0" ixz="0"
               iyy="0.00001" iyz="0" izz="0.00001"/>
    </inertial>
  </link>

  <!-- LiDAR -->
  <joint name="scan_joint" type="fixed">
    <parent link="base_link"/>
    <child link="base_scan"/>
    <origin xyz="-0.032 0 0.172" rpy="0 0 0"/>
  </joint>

  <link name="base_scan">
    <visual>
      <geometry>
        <cylinder radius="0.035" length="0.018"/>
      </geometry>
      <material name="dark_grey"/>
    </visual>
    <collision>
      <geometry>
        <cylinder radius="0.035" length="0.018"/>
      </geometry>
    </collision>
    <inertial>
      <mass value="0.05"/>
      <inertia ixx="0.00001" ixy="0" ixz="0"
               iyy="0.00001" iyz="0" izz="0.00001"/>
    </inertial>
  </link>

  <!-- IMU -->
  <joint name="imu_joint" type="fixed">
    <parent link="base_link"/>
    <child link="imu_link"/>
    <origin xyz="0 0 0.068" rpy="0 0 0"/>
  </joint>

  <link name="imu_link"/>

</robot>
